C:\Users\¿Ã¿Ø¡¯\AppData\Local\Microsoft\WindowsApps\python.exe: can't open file 'C:\Users\Ïù¥Ïú†ÏßÑ\Desktop\Hardcarry\app.py': [Errno 2] No such file or directory
 * Serving Flask app 'rest_ex' (lazy loading)
 * Environment: production
   WARNING: This is a development server. Do not use it in a production deployment.
   Use a production WSGI server instead.
 * Debug mode: on
 * Restarting with stat
 * Debugger is active!
 * Debugger PIN: 143-855-929
 * Running on all addresses.
   WARNING: This is a development server. Do not use it in a production deployment.
 * Running on http://172.30.1.54:5000/ (Press CTRL+C to quit)
172.30.1.54 - - [08/Nov/2021 15:36:25] "GET / HTTP/1.1" 500 -
Traceback (most recent call last):
  File "C:\Users\¿Ã¿Ø¡¯\AppData\Local\Packages\PythonSoftwareFoundation.Python.3.9_qbz5n2kfra8p0\LocalCache\local-packages\Python39\site-packages\flask\app.py", line 2091, in __call__
    return self.wsgi_app(environ, start_response)
  File "C:\Users\¿Ã¿Ø¡¯\AppData\Local\Packages\PythonSoftwareFoundation.Python.3.9_qbz5n2kfra8p0\LocalCache\local-packages\Python39\site-packages\flask\app.py", line 2076, in wsgi_app
    response = self.handle_exception(e)
  File "C:\Users\¿Ã¿Ø¡¯\AppData\Local\Packages\PythonSoftwareFoundation.Python.3.9_qbz5n2kfra8p0\LocalCache\local-packages\Python39\site-packages\flask\app.py", line 2073, in wsgi_app
    response = self.full_dispatch_request()
  File "C:\Users\¿Ã¿Ø¡¯\AppData\Local\Packages\PythonSoftwareFoundation.Python.3.9_qbz5n2kfra8p0\LocalCache\local-packages\Python39\site-packages\flask\app.py", line 1518, in full_dispatch_request
    rv = self.handle_user_exception(e)
  File "C:\Users\¿Ã¿Ø¡¯\AppData\Local\Packages\PythonSoftwareFoundation.Python.3.9_qbz5n2kfra8p0\LocalCache\local-packages\Python39\site-packages\flask\app.py", line 1516, in full_dispatch_request
    rv = self.dispatch_request()
  File "C:\Users\¿Ã¿Ø¡¯\AppData\Local\Packages\PythonSoftwareFoundation.Python.3.9_qbz5n2kfra8p0\LocalCache\local-packages\Python39\site-packages\flask\app.py", line 1502, in dispatch_request
    return self.ensure_sync(self.view_functions[rule.endpoint])(**req.view_args)
  File "C:\Users\¿Ã¿Ø¡¯\Desktop\Hardcarry\rest_ex.py", line 8, in home
    return render_template('index.html')
  File "C:\Users\¿Ã¿Ø¡¯\AppData\Local\Packages\PythonSoftwareFoundation.Python.3.9_qbz5n2kfra8p0\LocalCache\local-packages\Python39\site-packages\flask\templating.py", line 148, in render_template
    ctx.app.jinja_env.get_or_select_template(template_name_or_list),
  File "C:\Users\¿Ã¿Ø¡¯\AppData\Local\Packages\PythonSoftwareFoundation.Python.3.9_qbz5n2kfra8p0\LocalCache\local-packages\Python39\site-packages\jinja2\environment.py", line 1068, in get_or_select_template
    return self.get_template(template_name_or_list, parent, globals)
  File "C:\Users\¿Ã¿Ø¡¯\AppData\Local\Packages\PythonSoftwareFoundation.Python.3.9_qbz5n2kfra8p0\LocalCache\local-packages\Python39\site-packages\jinja2\environment.py", line 997, in get_template
    return self._load_template(name, globals)
  File "C:\Users\¿Ã¿Ø¡¯\AppData\Local\Packages\PythonSoftwareFoundation.Python.3.9_qbz5n2kfra8p0\LocalCache\local-packages\Python39\site-packages\jinja2\environment.py", line 958, in _load_template
    template = self.loader.load(self, name, self.make_globals(globals))
  File "C:\Users\¿Ã¿Ø¡¯\AppData\Local\Packages\PythonSoftwareFoundation.Python.3.9_qbz5n2kfra8p0\LocalCache\local-packages\Python39\site-packages\jinja2\loaders.py", line 125, in load
    source, filename, uptodate = self.get_source(environment, name)
  File "C:\Users\¿Ã¿Ø¡¯\AppData\Local\Packages\PythonSoftwareFoundation.Python.3.9_qbz5n2kfra8p0\LocalCache\local-packages\Python39\site-packages\flask\templating.py", line 59, in get_source
    return self._get_source_fast(environment, template)
  File "C:\Users\¿Ã¿Ø¡¯\AppData\Local\Packages\PythonSoftwareFoundation.Python.3.9_qbz5n2kfra8p0\LocalCache\local-packages\Python39\site-packages\flask\templating.py", line 95, in _get_source_fast
    raise TemplateNotFound(template)
jinja2.exceptions.TemplateNotFound: index.html
172.30.1.54 - - [08/Nov/2021 15:36:26] "GET /?__debugger__=yes&cmd=resource&f=style.css HTTP/1.1" 200 -
172.30.1.54 - - [08/Nov/2021 15:36:26] "GET /?__debugger__=yes&cmd=resource&f=debugger.js HTTP/1.1" 200 -
172.30.1.54 - - [08/Nov/2021 15:36:26] "GET /?__debugger__=yes&cmd=resource&f=console.png HTTP/1.1" 200 -
172.30.1.54 - - [08/Nov/2021 15:36:26] "GET /?__debugger__=yes&cmd=resource&f=ubuntu.ttf HTTP/1.1" 200 -
172.30.1.54 - - [08/Nov/2021 15:36:26] "GET /?__debugger__=yes&cmd=resource&f=console.png HTTP/1.1" 200 -
192.168.25.25 - - [08/Nov/2021 17:02:56] "GET / HTTP/1.1" 500 -
Traceback (most recent call last):
  File "C:\Users\¿Ã¿Ø¡¯\AppData\Local\Packages\PythonSoftwareFoundation.Python.3.9_qbz5n2kfra8p0\LocalCache\local-packages\Python39\site-packages\flask\app.py", line 2091, in __call__
    return self.wsgi_app(environ, start_response)
  File "C:\Users\¿Ã¿Ø¡¯\AppData\Local\Packages\PythonSoftwareFoundation.Python.3.9_qbz5n2kfra8p0\LocalCache\local-packages\Python39\site-pack * Detected change in 'C:\\Users\\¿Ã¿Ø¡¯\\Desktop\\Hardcarry\\app.py', reloading
 * Restarting with stat
C:\Users\¿Ã¿Ø¡¯\AppData\Local\Microsoft\WindowsApps\PythonSoftwareFoundation.Python.3.9_qbz5n2kfra8p0\python.exe: can't open file 'C:\Users\Ïù¥Ïú†ÏßÑ\Desktop\Hardcarry\rest_ex.py': [Errno 2] No such file or directory
:\Users\¿Ã¿Ø¡¯\AppData\Local\Packages\PythonSoftwareFoundation.Python.3.9_qbz5n2kfra8p0\LocalCache\local-packages\Python39\site-packages\flask\app.py", line 1518, in full_dispatch_request
    rv = self.handle_user_exception(e)
  File "C:\Users\¿Ã¿Ø¡¯\AppData\Local\Packages\PythonSoftwareFoundation.Python.3.9_qbz5n2kfra8p0\LocalCache\local-packages\Python39\site-packages\flask\app.py", line 1516, in full_dispatch_request
    rv = self.dispatch_request()
  File "C:\Users\¿Ã¿Ø¡¯\AppData\Local\Packages\PythonSoftwareFoundation.Python.3.9_qbz5n2kfra8p0\LocalCache\local-packages\Python39\site-packages\flask\app.py", line 1502, in dispatch_request
    return self.ensure_sync(self.view_functions[rule.endpoint])(**req.view_args)
  File "C:\Users\¿Ã¿Ø¡¯\Desktop\Hardcarry\rest_ex.py", line 8, in home
    return render_template('index.html')
  File "C:\Users\¿Ã¿Ø¡¯\AppData\Local\Packages\PythonSoftwareFoundation.Python.3.9_qbz5n2kfra8p0\LocalCache\local-packages\Python39\site-packages\flask\templating.py", line 148, in render_template
    ctx.app.jinja_env.get_or_select_template(template_name_or_list),
  File "C:\Users\¿Ã¿Ø¡¯\AppData\Local\Packages\PythonSoftwareFoundation.Python.3.9_qbz5n2kfra8p0\LocalCache\local-packages\Python39\site-packages\jinja2\environment.py", line 1068, in get_or_select_template
    return self.get_template(template_name_or_list, parent, globals)
  File "C:\Users\¿Ã¿Ø¡¯\AppData\Local\Packages\PythonSoftwareFoundation.Python.3.9_qbz5n2kfra8p0\LocalCache\local-packages\Python39\site-packages\jinja2\environment.py", line 997, in get_template
    return self._load_template(name, globals)
  File "C:\Users\¿Ã¿Ø¡¯\AppData\Local\Packages\PythonSoftwareFoundation.Python.3.9_qbz5n2kfra8p0\LocalCache\local-packages\Python39\site-packages\jinja2\environment.py", line 958, in _load_template
    template = self.loader.load(self, name, self.make_globals(globals))
  File "C:\Users\¿Ã¿Ø¡¯\AppData\Local\Packages\PythonSoftwareFoundation.Python.3.9_qbz5n2kfra8p0\LocalCache\local-packages\Python39\site-packages\jinja2\loaders.py", line 125, in load
    source, filename, uptodate = self.get_source(environment, name)
  File "C:\Users\¿Ã¿Ø¡¯\AppData\Local\Packages\PythonSoftwareFoundation.Python.3.9_qbz5n2kfra8p0\LocalCache\local-packages\Python39\site-packages\flask\templating.py", line 59, in get_source
    return self._get_source_fast(environment, template)
  File "C:\Users\¿Ã¿Ø¡¯\AppData\Local\Packages\PythonSoftwareFoundation.Python.3.9_qbz5n2kfra8p0\LocalCache\local-packages\Python39\site-packages\flask\templating.py", line 95, in _get_source_fast
    raise TemplateNotFound(template)
jinja2.exceptions.TemplateNotFound: index.html
192.168.25.25 - - [08/Nov/2021 17:02:57] "GET /?__debugger__=yes&cmd=resource&f=style.css HTTP/1.1" 200 -
192.168.25.25 - - [08/Nov/2021 17:02:57] "GET / HTTP/1.1" 500 -
192.168.25.25 - - [08/Nov/2021 17:02:57] "GET /?__debugger__=yes&cmd=resource&f=debugger.js HTTP/1.1" 200 -
Traceback (most recent call last):
  File "C:\Users\¿Ã¿Ø¡¯\AppData\Local\Packages\PythonSoftwareFoundation.Python.3.9_qbz5n2kfra8p0\LocalCache\local-packages\Python39\site-packages\flask\app.py", line 2091, in __call__
    return self.wsgi_app(environ, start_response)
  File "C:\Users\¿Ã¿Ø¡¯\AppData\Local\Packages\PythonSoftwareFoundation.Python.3.9_qbz5n2kfra8p0\LocalCache\local-packages\Python39\site-packages\flask\app.py", line 2076, in wsgi_app
    response = self.handle_exception(e)
  File "C:\Users\¿Ã¿Ø¡¯\AppData\Local\Packages\PythonSoftwareFoundation.Python.3.9_qbz5n2kfra8p0\LocalCache\local-packages\Python39\site-packages\flask\app.py", line 2073, in wsgi_app
    response = self.full_dispatch_request()
  File "C:\Users\¿Ã¿Ø¡¯\AppData\Local\Packages\PythonSoftwareFoundation.Python.3.9_qbz5n2kfra8p0\LocalCache\local-packages\Python39\site-packages\flask\app.py", line 1518, in full_dispatch_request
    rv = self.handle_user_exception(e)
  File "C:\Users\¿Ã¿Ø¡¯\AppData\Local\Packages\PythonSoftwareFoundation.Python.3.9_qbz5n2kfra8p0\LocalCache\local-packages\Python39\site-packages\flask\app.py", line 1516, in full_dispatch_request
    rv = self.dispatch_request()
  File "C:\Users\¿Ã¿Ø¡¯\AppData\Local\Packages\PythonSoftwareFoundation.Python.3.9_qbz5n2kfra8p0\LocalCache\local-packages\Python39\site-packages\flask\app.py", line 1502, in dispatch_request
    return self.ensure_sync(self.view_functions[rule.endpoint])(**req.view_args)
  File "C:\Users\¿Ã¿Ø¡¯\Desktop\Hardcarry\rest_ex.py", line 8, in home
    return render_template('index.html')
  File "C:\Users\¿Ã¿Ø¡¯\AppData\Local\Packages\PythonSoftwareFoundation.Python.3.9_qbz5n2kfra8p0\LocalCache\local-packages\Python39\site-packages\flask\templating.py", line 148, in render_template
    ctx.app.jinja_env.get_or_select_template(template_name_or_list),
  File "C:\Users\¿Ã¿Ø¡¯\AppData\Local\Packages\PythonSoftwareFoundation.Python.3.9_qbz5n2kfra8p0\LocalCache\local-packages\Python39\site-packages\jinja2\environment.py", line 1068, in get_or_select_template
    return self.get_template(template_name_or_list, parent, globals)
  File "C:\Users\¿Ã¿Ø¡¯\AppData\Local\Packages\PythonSoftwareFoundation.Python.3.9_qbz5n2kfra8p0\LocalCache\local-packages\Python39\site-packages\jinja2\environment.py", line 997, in get_template
    return self._load_template(name, globals)
  File "C:\Users\¿Ã¿Ø¡¯\AppData\Local\Packages\PythonSoftwareFoundation.Python.3.9_qbz5n2kfra8p0\LocalCache\local-packages\Python39\site-packages\jinja2\environment.py", line 958, in _load_template
    template = self.loader.load(self, name, self.make_globals(globals))
  File "C:\Users\¿Ã¿Ø¡¯\AppData\Local\Packages\PythonSoftwareFoundation.Python.3.9_qbz5n2kfra8p0\LocalCache\local-packages\Python39\site-packages\jinja2\loaders.py", line 125, in load
    source, filename, uptodate = self.get_source(environment, name)
  File "C:\Users\¿Ã¿Ø¡¯\AppData\Local\Packages\PythonSoftwareFoundation.Python.3.9_qbz5n2kfra8p0\LocalCache\local-packages\Python39\site-packages\flask\templating.py", line 59, in get_source
    return self._get_source_fast(environment, template)
  File "C:\Users\¿Ã¿Ø¡¯\AppData\Local\Packages\PythonSoftwareFoundation.Python.3.9_qbz5n2kfra8p0\LocalCache\local-packages\Python39\site-packages\flask\templating.py", line 95, in _get_source_fast
    raise TemplateNotFound(template)
jinja2.exceptions.TemplateNotFound: index.html
192.168.25.25 - - [08/Nov/2021 17:02:57] "GET /?__debugger__=yes&cmd=resource&f=console.png HTTP/1.1" 200 -
192.168.25.25 - - [08/Nov/2021 17:02:57] "GET /?__debugger__=yes&cmd=resource&f=style.css HTTP/1.1" 200 -
192.168.25.25 - - [08/Nov/2021 17:02:57] "GET /?__debugger__=yes&cmd=resource&f=debugger.js HTTP/1.1" 200 -
192.168.25.25 - - [08/Nov/2021 17:02:57] "GET /?__debugger__=yes&cmd=resource&f=console.png HTTP/1.1" 200 -
192.168.25.25 - - [08/Nov/2021 17:02:57] "GET /?__debugger__=yes&cmd=resource&f=ubuntu.ttf HTTP/1.1" 200 -
192.168.25.25 - - [08/Nov/2021 17:02:57] "GET /?__debugger__=yes&cmd=resource&f=console.png HTTP/1.1" 200 -
192.168.25.25 - - [08/Nov/2021 17:02:57] "GET /?__debugger__=yes&cmd=resource&f=ubuntu.ttf HTTP/1.1" 200 -
192.168.25.25 - - [08/Nov/2021 17:03:28] "GET / HTTP/1.1" 200 -
192.168.25.25 - - [08/Nov/2021 17:03:28] "GET /favicon.ico HTTP/1.1" 404 -
192.168.25.25 - - [08/Nov/2021 17:03:29] "GET / HTTP/1.1" 200 -
 * Detected change in 'C:\\Users\\¿Ã¿Ø¡¯\\Desktop\\Hardcarry\\app.py', reloading
 * Restarting with stat
C:\Users\¿Ã¿Ø¡¯\AppData\Local\Microsoft\WindowsApps\PythonSoftwareFoundation.Python.3.9_qbz5n2kfra8p0\python.exe: can't open file 'C:\Users\Ïù¥Ïú†ÏßÑ\Desktop\Hardcarry\rest_ex.py': [Errno 2] No such file or directory
